<?xml version="1.0"?>
<robot name="arm">
	<link name="base_link">
	</link>

	<link name="arm_base">
		<visual>
			<geometry>
				<mesh filename="package://arm_ros_conn/meshes/32985.stl"/>
			</geometry>
			<material name="black">
				<color rgba="0 0 0 1"/>
			</material>
		</visual>
	</link>

	<link name="link1">
		<visual>
			<geometry>
				<box size="0.06 0.03 0.123"/>
			</geometry>
			<origin xyz="0 0 0.0615"/>
			<material name="grey">
				<color rgba="0.5 0.5 0.5 1"/>
			</material>
		</visual>
	</link>

	<link name="link2">
		<visual>
			<geometry>
				<box size="0.240 0.06 0.03"/>
			</geometry>
			<origin xyz="0.120 0 0.0" rpy="0 0 0"/>
			<material name="grey">
				<color rgba="0.5 0.5 0.5 1"/>
			</material>
		</visual>
	</link>

	<link name="link3">
		<visual>
			<geometry>
				<box size="0.06 0.135 0.03"/>
			</geometry>
			<origin xyz="0.0 0.0675 0.0" rpy="0 0 0"/>
			<material name="grey">
				<color rgba="0.5 0.5 0.5 1"/>
			</material>
		</visual>
	</link>

	<link name="link4">
		<visual>
			<geometry>
				<cylinder radius="0.045" length="0.03"/>
			</geometry>
			<origin xyz="0.015 0 0" rpy="0 1.57075 0"/>
			<material name="black">
				<color rgba="0 0 0 1"/>
			</material>
		</visual>
	</link>

	<link name="link5">
		<visual>
			<geometry>
				<mesh filename="package://arm_ros_conn/meshes/31019.stl"/>
			</geometry>
			<origin xyz="0.0 0 0" rpy="1.57075 0 0"/>
			<material name="red">
				<color rgba="1 0 0 1"/>
			</material>
		</visual>
	</link>

	<link name="gripper_pole">
	</link>

	<link name="left_gripper">
		<visual>
			<origin xyz="0.025 0 0" rpy="-1.57075 3.1415 0"/>
			<geometry>
				<mesh filename="package://arm_ros_conn/meshes/35978.stl" scale="0.001 0.001 0.001"/>
			</geometry>
			<material name="red">
				<color rgba="1 0 0 1"/>
			</material>
		</visual>
	</link>

	<link name="right_gripper">
		<visual>
			<origin xyz="0.025 0 0" rpy="1.57075 3.1415 0"/>
			<geometry>
				<mesh filename="package://arm_ros_conn/meshes/35978.stl" scale="0.001 0.001 0.001"/>
			</geometry>
			<material name="red">
				<color rgba="1 0 0 1"/>
			</material>
		</visual>
	</link>

	<joint name="base_link_to_arm_base" type="fixed">
		<parent link="base_link"/>
		<child link="arm_base"/>
		<origin xyz="0 0 0.00375"/>
	</joint>

	<joint name="arm_base_to_link1" type="revolute">
		<parent link="arm_base"/>
		<child link="link1"/>
		<axis xyz="0 0 1"/>
		<origin xyz="0 0.099 0"/>
		<limit effort="1000.0" lower="-5.672320068981571" upper="0.0" velocity="1.0"/>
	</joint>

	<joint name="link_1_2_joint" type="revolute">
		<parent link="link1"/>
		<child link="link2"/>
		<axis xyz="0 0 1"/>
		<origin xyz="0.0 0.0 0.123" rpy="1.57075 0 0"/>
		<limit effort="1000.0" lower="0.15045941827537324" upper="3.6110260386089577" velocity="1.0"/>
	</joint>

	<joint name="link_2_3_joint" type="revolute">
		<parent link="link2"/>
		<child link="link3"/>
		<axis xyz="0 0 1"/>
		<origin xyz="0.240 0.0 0.0" rpy="0 0 0"/>
		<limit effort="1000.0" lower="-3.141592653589793" upper="0.0" velocity="1.0"/>
	</joint>

	<joint name="link_3_4_joint" type="revolute">
		<parent link="link3"/>
		<child link="link4"/>
		<axis xyz="1 0 0"/>
		<origin xyz="0 0.135 0.0" rpy="1.57075 0 1.57075"/>
		<limit effort="1000.0" lower="-5.4978" upper="0.15708" velocity="1.0"/>
	</joint>

	<joint name="link_4_5_joint" type="revolute">
		<parent link="link4"/>
		<child link="link5"/>
		<axis xyz="0 1 0"/>
		<origin xyz="0.06 0.0 0.0" rpy="0 0 0"/>
		<limit effort="1000.0" lower="-1.5707963267948966" upper="1.5707963267948966" velocity="1.0"/>
	</joint>

	<joint name="gripper_pole_joint" type="fixed">
		<parent link="link5"/>
		<child link="gripper_pole"/>
	</joint>

	<joint name="left_gripper_joint" type="revolute">
		<parent link="gripper_pole"/>
		<child link="left_gripper"/>
		<axis xyz="0 0 1"/>
		<origin xyz="0.02 0.01 0" rpy="0 0 0" />
		<limit effort="1000.0" lower="0.0" upper="0.35" velocity="1.0"/>
	</joint>

	<joint name="right_gripper_joint" type="revolute">
		<parent link="gripper_pole"/>
		<child link="right_gripper"/>
		<axis xyz="0 0 -1"/>
		<origin xyz="0.02 -0.01 0" rpy="0 0 0"/>
		<limit effort="1000.0" lower="0.0" upper="0.35" velocity="1.0"/>
	</joint>
</robot>
